File: MTP/stress_strain.csv
True Stress (MPa),True Strain
320,0.01
360,0.02
395,0.03
420,0.04
440,0.05
455,0.06
470,0.07
480,0.08
490,0.09
500,0.1
510,0.11
520,0.12
530,0.13
540,0.14
545,0.15
550,0.16